Workbook

Sheet Protheus
A1: CODIGO | B1: DENOMINACION | C1: TD | D1: Nº DOCUMENTO | E1: IVA | F1: FECHA | G1: ESP | H1: SERIE | I1: NUMERO | J1: % IVA | K1: TOTAL | L1: GRAVADO | M1: EXEN/NO GRAV | N1: IVA | O1: IVA Percep | P1: IIBB Percep | Q1: OTROS | R1: EXCL.NET.GRAV | S1: Unido | T1: AFIP IVA | U1: Cmparacion IVA | V1: AFIP Total | W1: Cmparacion Total
A2: 000967 | B2: ZEOCAR SACI | C2: 80 | D2: 30562597464 | E2: I | F2: 22/09/2025 | G2: NCP | H2: A1 | I2: 000400025904 | J2: 21 | K2: -459949.14 | L2: -380123.26 | M2: 0 | N2: -79825.88 | O2: 0 | P2: 0 | Q2: 0 | R2: 0 | S2: =D2&I2 -> 30562597464000400025904 | T2: =IFERROR(VLOOKUP(S2,AFIP!$F$2:$R$999999,12,FALSE),"NO") -> NO | U2: =IF(N2=T2,"SI","NO") -> NO | V2: =IFERROR(VLOOKUP(S2,AFIP!$F$2:$R$999999,13,FALSE),"NO") -> NO | W2: =IF(K2=V2,"SI","NO") -> NO
A3: 000015 | B3: ESCALERAS SIN FIN SOCIEDAD DE HECHO | C3: 80 | D3: 33620532229 | E3: I | F3: 01/10/2025 | G3: NCP | H3: A1 | I3: 000200007977 | J3: 21 | K3: -206388.15 | L3: -170568.72 | M3: 0 | N3: -35819.43 | O3: 0 | P3: 0 | Q3: 0 | R3: 0 | S3: =D3&I3 -> 33620532229000200007977 | T3: =IFERROR(VLOOKUP(S3,AFIP!$F$2:$R$999999,12,FALSE),"NO") -> NO | U3: =IF(N3=T3,"SI","NO") -> NO | V3: =IFERROR(VLOOKUP(S3,AFIP!$F$2:$R$999999,13,FALSE),"NO") -> NO | W3: =IF(K3=V3,"SI","NO") -> NO
A4: 000001 | B4: AKZO NOBEL S.A. - (ALBA & CETOL) | C4: 80 | D4: 30500529454 | E4: I | F4: 03/10/2025 | G4: NCP | H4: A1 | I4: 026700171598 | J4: 21 | K4: -207657.9 | L4: -97841.1 | M4: 0 | N4: -20546.64 | O4: -2935.23 | P4: -2446.03 | Q4: -83888.9 | R4: 0 | S4: =D4&I4 -> 30500529454026700171598 | T4: =IFERROR(VLOOKUP(S4,AFIP!$F$2:$R$999999,12,FALSE),"NO") -> NO | U4: =IF(N4=T4,"SI","NO") -> NO | V4: =IFERROR(VLOOKUP(S4,AFIP!$F$2:$R$999999,13,FALSE),"NO") -> NO | W4: =IF(K4=V4,"SI","NO") -> NO
A5: 000015 | B5: ESCALERAS SIN FIN SOCIEDAD DE HECHO | C5: 80 | D5: 33620532229 | E5: I | F5: 07/10/2025 | G5: NCP | H5: A1 | I5: 000200007985 | J5: 21 | K5: -1506196 | L5: -1244790.1 | M5: 0 | N5: -261405.92 | O5: 0 | P5: 0 | Q5: 0 | R5: 0 | S5: =D5&I5 -> 33620532229000200007985 | T5: =IFERROR(VLOOKUP(S5,AFIP!$F$2:$R$999999,12,FALSE),"NO") -> NO | U5: =IF(N5=T5,"SI","NO") -> NO | V5: =IFERROR(VLOOKUP(S5,AFIP!$F$2:$R$999999,13,FALSE),"NO") -> NO | W5: =IF(K5=V5,"SI","NO") -> NO
A6: 000300 | B6: A A ABRASIVOS ARGENTINOS S.A.I.C. | C6: 80 | D6: 30501044551 | E6: I | F6: 08/10/2025 | G6: NCP | H6: A1 | I6: 000700219976 | J6: 21 | K6: -126936.9 | L6: -30431.38 | M6: 0 | N6: -6390.59 | O6: -912.94 | P6: -760.78 | Q6: -88441.21 | R6: 0 | S6: =D6&I6 -> 30501044551000700219976 | T6: =IFERROR(VLOOKUP(S6,AFIP!$F$2:$R$999999,12,FALSE),"NO") -> NO | U6: =IF(N6=T6,"SI","NO") -> NO | V6: =IFERROR(VLOOKUP(S6,AFIP!$F$2:$R$999999,13,FALSE),"NO") -> NO | W6: =IF(K6=V6,"SI","NO") -> NO
A7: 000001 | B7: AKZO NOBEL S.A. - (ALBA & CETOL) | C7: 80 | D7: 30500529454 | E7: I | F7: 16/10/2025 | G7: NCP | H7: A1 | I7: 026700171749 | J7: 21 | K7: -75705.97 | L7: -62566.92 | M7: 0 | N7: -13139.05 | O7: 0 | P7: 0 | Q7: 0 | R7: 0 | S7: =D7&I7 -> 30500529454026700171749 | T7: =IFERROR(VLOOKUP(S7,AFIP!$F$2:$R$999999,12,FALSE),"NO") -> NO | U7: =IF(N7=T7,"SI","NO") -> NO | V7: =IFERROR(VLOOKUP(S7,AFIP!$F$2:$R$999999,13,FALSE),"NO") -> NO | W7: =IF(K7=V7,"SI","NO") -> NO
A8: 000039 | B8: PREPAN S.A | C8: 80 | D8: 33522734549 | E8: I | F8: 23/10/2025 | G8: NCP | H8: A1 | I8: 002100242470 | J8: 21 | K8: -1668181.7 | L8: -1345307.8 | M8: 0 | N8: -282514.64 | O8: -40359.23 | P8: 0 | Q8: 0 | R8: 0 | S8: =D8&I8 -> 33522734549002100242470 | T8: =IFERROR(VLOOKUP(S8,AFIP!$F$2:$R$999999,12,FALSE),"NO") -> NO | U8: =IF(N8=T8,"SI","NO") -> NO | V8: =IFERROR(VLOOKUP(S8,AFIP!$F$2:$R$999999,13,FALSE),"NO") -> NO | W8: =IF(K8=V8,"SI","NO") -> NO
A9: 000039 | B9: PREPAN S.A | C9: 80 | D9: 33522734549 | E9: I | F9: 23/10/2025 | G9: NCP | H9: A1 | I9: 002100242471 | J9: 21 | K9: -2276867.9 | L9: -1836183.8 | M9: 0 | N9: -385598.6 | O9: -55085.51 | P9: 0 | Q9: 0 | R9: 0 | S9: =D9&I9 -> 33522734549002100242471 | T9: =IFERROR(VLOOKUP(S9,AFIP!$F$2:$R$999999,12,FALSE),"NO") -> NO | U9: =IF(N9=T9,"SI","NO") -> NO | V9: =IFERROR(VLOOKUP(S9,AFIP!$F$2:$R$999999,13,FALSE),"NO") -> NO | W9: =IF(K9=V9,"SI","NO") -> NO
A10: 000039 | B10: PREPAN S.A | C10: 80 | D10: 33522734549 | E10: I | F10: 23/10/2025 | G10: NCP | H10: A1 | I10: 002100242472 | J10: 21 | K10: -5106.02 | L10: -4117.76 | M10: 0 | N10: -864.73 | O10: -123.53 | P10: 0 | Q10: 0 | R10: 0 | S10: =D10&I10 -> 33522734549002100242472 | T10: =IFERROR(VLOOKUP(S10,AFIP!$F$2:$R$999999,12,FALSE),"NO") -> NO | U10: =IF(N10=T10,"SI","NO") -> NO | V10: =IFERROR(VLOOKUP(S10,AFIP!$F$2:$R$999999,13,FALSE),"NO") -> NO | W10: =IF(K10=V10,"SI","NO") -> NO
A11: 000039 | B11: PREPAN S.A | C11: 80 | D11: 33522734549 | E11: I | F11: 23/10/2025 | G11: NCP | H11: A1 | I11: 002100242473 | J11: 21 | K11: -26593.75 | L11: -21446.57 | M11: 0 | N11: -4503.78 | O11: -643.4 | P11: 0 | Q11: 0 | R11: 0 | S11: =D11&I11 -> 33522734549002100242473 | T11: =IFERROR(VLOOKUP(S11,AFIP!$F$2:$R$999999,12,FALSE),"NO") -> NO | U11: =IF(N11=T11,"SI","NO") -> NO | V11: =IFERROR(VLOOKUP(S11,AFIP!$F$2:$R$999999,13,FALSE),"NO") -> NO | W11: =IF(K11=V11,"SI","NO") -> NO
A12: 000039 | B12: PREPAN S.A | C12: 80 | D12: 33522734549 | E12: I | F12: 23/10/2025 | G12: NCP | H12: A1 | I12: 002100242474 | J12: 21 | K12: -383572.04 | L12: -309332.29 | M12: 0 | N12: -64959.78 | O12: -9279.97 | P12: 0 | Q12: 0 | R12: 0 | S12: =D12&I12 -> 33522734549002100242474 | T12: =IFERROR(VLOOKUP(S12,AFIP!$F$2:$R$999999,12,FALSE),"NO") -> NO | U12: =IF(N12=T12,"SI","NO") -> NO | V12: =IFERROR(VLOOKUP(S12,AFIP!$F$2:$R$999999,13,FALSE),"NO") -> NO | W12: =IF(K12=V12,"SI","NO") -> NO
A13: 000102 | B13: FAIP S.A.I.C | C13: 80 | D13: 30523412236 | E13: I | F13: 24/10/2025 | G13: NCP | H13: A1 | I13: 001400012737 | J13: 21 | K13: -1089740 | L13: -900611.59 | M13: 0 | N13: -189128.43 | O13: 0 | P13: 0 | Q13: 0 | R13: 0 | S13: =D13&I13 -> 30523412236001400012737 | T13: =IFERROR(VLOOKUP(S13,AFIP!$F$2:$R$999999,12,FALSE),"NO") -> NO | U13: =IF(N13=T13,"SI","NO") -> NO | V13: =IFERROR(VLOOKUP(S13,AFIP!$F$2:$R$999999,13,FALSE),"NO") -> NO | W13: =IF(K13=V13,"SI","NO") -> NO
... A601: Z9999O | B601: GROSS SERGIO FABIAN | C601: 80 | D601: 23179973219 | E601: M | F601: 30/11/2025 | G601: NF | H601: C | I601: 000200001053 | J601: 0 | K601: 72000 | L601: 0 | M601: 72000 | N601: 0 | O601: 0 | P601: 0 | Q601: 0 | R601: 0 | S601: =D601&I601 -> 23179973219000200001053 | T601: =IFERROR(VLOOKUP(S601,AFIP!$F$2:$R$999999,12,FALSE),"NO") -> NO | U601: =IF(N601=T601,"SI","NO") -> NO | V601: =IFERROR(VLOOKUP(S601,AFIP!$F$2:$R$999999,13,FALSE),"NO") -> NO | W601: =IF(K601=V601,"SI","NO") -> NO

Sheet AFIP
A1: Fecha | B1: Tipo | C1: Punto de Venta | D1: Número Desde | E1: Doc Completo | F1: Unido | G1: Cód. Autorización | H1: Tipo Doc. Emisor | I1: Nro. Doc. Emisor | J1: Denominación Emisor | K1: Tipo Cambio | L1: Moneda | M1: Imp. Neto Gravado | N1: Imp. Neto No Gravado | O1: Imp. Op. Exentas | P1: Otros Tributos | Q1: IVA | R1: Imp. Total
A2: 45962 | B2: 1 | C2: 3 | D2: 109597 | E2: =TEXT(C2,"0000")&TEXT(D2,"00000000") -> 000300109597 | F2: =I2&E2 -> 30708762373000300109597 | G2: 75443659659757 | H2: 80 | I2: 30708762373 | J2: FIDEICOMISO ENTRE OFEK S.A. , OSVALDO BESNOSOFF Y OTROS | K2: 1 | L2: $ | M2: 27685.95 | N2: 0 | O2: 0 | P2: 0 | Q2: 5814.05 | R2: 33500
A3: 45962 | B3: 1 | C3: 3 | D3: 15537 | E3: =TEXT(C3,"0000")&TEXT(D3,"00000000") -> 000300015537 | F3: =I3&E3 -> 30715919792000300015537 | G3: 75442086050641 | H3: 80 | I3: 30715919792 | J3: CAPASITIO S.A.S. | K3: 1 | L3: $ | M3: 163509.55 | N3: 0 | O3: 0 | P3: 0 | Q3: 34337.01 | R3: 197846.56
A4: 45962 | B4: 1 | C4: 24 | D4: 12051 | E4: =TEXT(C4,"0000")&TEXT(D4,"00000000") -> 002400012051 | F4: =I4&E4 -> 33681952239002400012051 | G4: 75449067401105 | H4: 80 | I4: 33681952239 | J4: TELECABLE COLOR RINCON SRL | K4: 1 | L4: $ | M4: 14876.03 | N4: 0 | O4: 0 | P4: 0 | Q4: 3123.97 | R4: 18000
A5: 45962 | B5: 1 | C5: 2 | D5: 66062 | E5: =TEXT(C5,"0000")&TEXT(D5,"00000000") -> 000200066062 | F5: =I5&E5 -> 30708506237000200066062 | G5: 75447084285249 | H5: 80 | I5: 30708506237 | J5: EXPRESO 3 C SRL | K5: 1 | L5: $ | M5: 130709.95 | N5: 0 | O5: 0 | P5: 0 | Q5: 27449.09 | R5: 158159.04
A6: 45962 | B6: 1 | C6: 711 | D6: 7789834 | E6: =TEXT(C6,"0000")&TEXT(D6,"00000000") -> 071107789834 | F6: =I6&E6 -> 30677237119071107789834 | G6: 35439383462793 | H6: 80 | I6: 30677237119 | J6: AUTOPISTAS DEL SOL S A | K6: 1 | L6: $ | M6: 2657.75 | N6: 0 | O6: 79.73 | P6: 159.47 | Q6: 558.13 | R6: 3455.08
A7: 45962 | B7: 1 | C7: 629 | D7: 6608454 | E7: =TEXT(C7,"0000")&TEXT(D7,"00000000") -> 062906608454 | F7: =I7&E7 -> 30663498513062906608454 | G7: 35433970133027 | H7: 80 | I7: 30663498513 | J7: GRUPO CONCESIONARIO DEL OESTE SA | K7: 1 | L7: $ | M7: 3466.56 | N7: 0 | O7: 0 | P7: 207.99 | Q7: 727.98 | R7: 4402.53
A8: 45962 | B8: 1 | C8: 2 | D8: 10332 | E8: =TEXT(C8,"0000")&TEXT(D8,"00000000") -> 000200010332 | F8: =I8&E8 -> 30709715395000200010332 | G8: 75455673770393 | H8: 80 | I8: 30709715395 | J8: METROTEC S. A. | K8: 1 | L8: $ | M8: 1752300 | N8: 0 | O8: 0 | P8: 0 | Q8: 367983 | R8: 2120283
A9: 45962 | B9: 1 | C9: 2 | D9: 10333 | E9: =TEXT(C9,"0000")&TEXT(D9,"00000000") -> 000200010333 | F9: =I9&E9 -> 30709715395000200010333 | G9: 75455673877711 | H9: 80 | I9: 30709715395 | J9: METROTEC S. A. | K9: 1 | L9: $ | M9: 2570040 | N9: 0 | O9: 0 | P9: 0 | Q9: 539708.4 | R9: 3109748.4
A10: 45962 | B10: 1 | C10: 2 | D10: 10267 | E10: =TEXT(C10,"0000")&TEXT(D10,"00000000") -> 000200010267 | F10: =I10&E10 -> 30709715395000200010267 | G10: 75455672570597 | H10: 80 | I10: 30709715395 | J10: METROTEC S. A. | K10: 1 | L10: $ | M10: 1351100 | N10: 0 | O10: 0 | P10: 0 | Q10: 283731 | R10: 1634831
A11: 45962 | B11: 1 | C11: 9 | D11: 32 | E11: =TEXT(C11,"0000")&TEXT(D11,"00000000") -> 000900000032 | F11: =I11&E11 -> 27144014656000900000032 | G11: 75446090184621 | H11: 80 | I11: 27144014656 | J11: RICOBELLI ROSANA | K11: 1 | L11: $ | M11: 1150000 | N11: 0 | O11: 0 | P11: 0 | Q11: 241500 | R11: 1391500
A12: 45962 | B12: 6 | C12: 5 | D12: 10700 | E12: =TEXT(C12,"0000")&TEXT(D12,"00000000") -> 000500010700 | F12: =I12&E12 -> 20253290960000500010700 | G12: 75450444440972 | H12: 80 | I12: 20253290960 | J12: SACCONE SIMON | K12: 1 | L12: $ | M12: 0 | N12: 0 | O12: 0 | P12: 0 | Q12: 0 | R12: 120000
A13: 45962 | B13: 11 | C13: 3 | D13: 13 | E13: =TEXT(C13,"0000")&TEXT(D13,"00000000") -> 000300000013 | F13: =I13&E13 -> 27286259508000300000013 | G13: 75448989406969 | H13: 80 | I13: 27286259508 | J13: CRAVAREZZA RENATA | K13: 1 | L13: $ | M13: 0 | N13: 0 | O13: 0 | P13: 0 | Q13: 0 | R13: 1590000
... A29: 45964 | B29: 1 | C29: 1 | D29: 866 | E29: =TEXT(C29,"0000")&TEXT(D29,"00000000") -> 000100000866 | F29: =I29&E29 -> 30716314320000100000866 | G29: 75440294376563 | H29: 80 | I29: 30716314320 | J29: CONDOMINIO DE YPPOLITO DANIEL OSVALDO Y HESSEL LILIANA | K29: 1 | L29: $ | M29: 1035000 | N29: 0 | O29: 0 | P29: 0 | Q29: 217350 | R29: 1252350
A30: 45964 | B30: 1 | C30: 215 | D30: 100298 | E30: =TEXT(C30,"0000")&TEXT(D30,"00000000") -> 021500100298 | F30: =I30&E30 -> 30500529071021500100298 | G30: 35431670074949 | H30: 80 | I30: 30500529071 | J30: SAINT-GOBAIN ARGENTINA SA | K30: 1 | L30: $ | M30: 10778729 | P30: 592830.09 | Q30: 2263533.1 | R30: 13635092
A31: 45964 | B31: 3 | C31: 9 | D31: 27 | E31: =TEXT(C31,"0000")&TEXT(D31,"00000000") -> 000900000027 | F31: =I31&E31 -> 20335001932000900000027 | G31: 75442322873115 | H31: 80 | I31: 20335001932 | J31: VILLATA FERNANDO ARIEL | K31: 1 | L31: $ | M31: 12727.27 | N31: 0 | O31: 0 | P31: 0 | Q31: 2672.73 | R31: 15400
A32: 45964 | B32: 3 | C32: 2 | D32: 1444 | E32: =TEXT(C32,"0000")&TEXT(D32,"00000000") -> 000200001444 | F32: =I32&E32 -> 30714379468000200001444 | G32: 75448370338614 | H32: 80 | I32: 30714379468 | J32: PAINT & DETAIL S.R.L. | K32: 1 | L32: $ | M32: 3819 | N32: 0 | O32: 0 | P32: 0 | Q32: 801.99 | R32: 4620.99
A33: 45964 | B33: 3 | C33: 3 | D33: 847 | E33: =TEXT(C33,"0000")&TEXT(D33,"00000000") -> 000300000847 | F33: =I33&E33 -> 23174473919000300000847 | G33: 75449282856431 | H33: 80 | I33: 23174473919 | J33: TARIS JORGE LUIS | K33: 1 | L33: $ | M33: 46910.61 | N33: 0 | O33: 0 | P33: 0 | Q33: 9851.23 | R33: 56761.84
A34: 45964 | B34: 3 | C34: 5 | D34: 1875 | E34: =TEXT(C34,"0000")&TEXT(D34,"00000000") -> 000500001875 | F34: =I34&E34 -> 30707509976000500001875 | G34: 75446334904941 | H34: 80 | I34: 30707509976 | J34: ANGA S.A. | K34: 1 | L34: $ | M34: 64214.18 | N34: 0 | O34: 0 | P34: 0 | Q34: 13484.98 | R34: 77699.16
A35: 45964 | B35: 3 | C35: 201 | D35: 269929 | E35: =TEXT(C35,"0000")&TEXT(D35,"00000000") -> 020100269929 | F35: =I35&E35 -> 30500529071020100269929 | G35: 35431670074949 | H35: 80 | I35: 30500529071 | J35: SAINT-GOBAIN ARGENTINA SA | K35: 1 | L35: $ | M35: 538936.43 | P35: 16168.09 | Q35: 113176.65 | R35: 668281.19
A36: 45964 | B36: 6 | C36: 9 | D36: 19924 | E36: =TEXT(C36,"0000")&TEXT(D36,"00000000") -> 000900019924 | F36: =I36&E36 -> 20216414897000900019924 | G36: 75447317985785 | H36: 80 | I36: 20216414897 | J36: LONGONI FABIAN RAUL | K36: 1 | L36: $ | M36: 0 | N36: 0 | O36: 0 | P36: 0 | Q36: 0 | R36: 25767.02
A37: 45964 | B37: 11 | C37: 100 | D37: 1325670 | E37: =TEXT(C37,"0000")&TEXT(D37,"00000000") -> 010001325670 | F37: =I37&E37 -> 30567510138010001325670 | G37: 75438585782815 | H37: 80 | I37: 30567510138 | J37: ASOCIACION MUTUAL RURALISTA | K37: 1 | L37: $ | M37: 0 | N37: 0 | O37: 0 | P37: 0 | Q37: 0 | R37: 842432
A38: 45964 | B38: 11 | C38: 3 | D38: 143 | E38: =TEXT(C38,"0000")&TEXT(D38,"00000000") -> 000300000143 | F38: =I38&E38 -> 23292606389000300000143 | G38: 75449330606094 | H38: 80 | I38: 23292606389 | J38: CAPISANO ENRIQUE | K38: 1 | L38: $ | M38: 0 | N38: 0 | O38: 0 | P38: 0 | Q38: 0 | R38: 120000
A39: 45964 | B39: 11 | C39: 3 | D39: 918 | E39: =TEXT(C39,"0000")&TEXT(D39,"00000000") -> 000300000918 | F39: =I39&E39 -> 20314191294000300000918 | G39: 75444307728486 | H39: 80 | I39: 20314191294 | J39: BERTRAM JOSE LUIS | K39: 1 | L39: $ | M39: 0 | N39: 0 | O39: 0 | P39: 0 | Q39: 0 | R39: 50000
A40: 45964 | B40: 11 | C40: 1 | D40: 119 | E40: =TEXT(C40,"0000")&TEXT(D40,"00000000") -> 000100000119 | F40: =I40&E40 -> 20177222802000100000119 | G40: 75442408496530 | H40: 80 | I40: 20177222802 | J40: MULE JAVIER JOSE | K40: 1 | L40: $ | M40: 0 | N40: 0 | O40: 0 | P40: 0 | Q40: 0 | R40: 1212100
A41: 45964 | B41: 11 | C41: 1 | D41: 199 | E41: =TEXT(C41,"0000")&TEXT(D41,"00000000") -> 000100000199 | F41: =I41&E41 -> 27181583644000100000199 | G41: 75444392803487 | H41: 80 | I41: 27181583644 | J41: MIGNOLA ADRIANA ESTELA | K41: 1 | L41: $ | M41: 0 | N41: 0 | O41: 0 | P41: 0 | Q41: 0 | R41: 467000
A42: 45964 | B42: 11 | C42: 1 | D42: 98 | E42: =TEXT(C42,"0000")&TEXT(D42,"00000000") -> 000100000098 | F42: =I42&E42 -> 27301695689000100000098 | G42: 75459445457776 | H42: 80 | I42: 27301695689 | J42: CENA VANESA | K42: 1 | L42: $ | M42: 0 | N42: 0 | O42: 0 | P42: 0 | Q42: 0 | R42: 1625000
A43: 45964 | B43: 15 | C43: 2 | D43: 3003 | E43: =TEXT(C43,"0000")&TEXT(D43,"00000000") -> 000200003003 | F43: =I43&E43 -> 30681948623000200003003 | G43: 75433525242533 | H43: 80 | I43: 30681948623 | J43: ASOCIACION COOPERADORA POLICIAL DE ESPERANZA DEPARTAMENTO LAS COLONIAS PROVINCIA DE SANTA FE | K43: 1 | L43: $ | M43: 0 | N43: 0 | O43: 0 | P43: 0 | Q43: 0 | R43: 10000
A44: 45965 | B44: 1 | C44: 19 | D44: 3764 | E44: =TEXT(C44,"0000")&TEXT(D44,"00000000") -> 001900003764 | F44: =I44&E44 -> 30601652044001900003764 | G44: 75444439421858 | H44: 80 | I44: 30601652044 | J44: ELECTRICIDAD COLOMBO S.A. | K44: 1 | L44: $ | M44: 2588.32 | N44: 0 | O44: 0 | P44: 0 | Q44: 543.55 | R44: 3131.87
A45: 45965 | B45: 1 | C45: 4 | D45: 17859 | E45: =TEXT(C45,"0000")&TEXT(D45,"00000000") -> 000400017859 | F45: =I45&E45 -> 20062436965000400017859 | G45: 75445473271275 | H45: 80 | I45: 20062436965 | J45: BOTTAI ALBERTO ARTURO | K45: 1 | L45: $ | M45: 915996.85 | N45: 0 | O45: 0 | P45: 0 | Q45: 192359.34 | R45: 1108356.2
A46: 45965 | B46: 1 | C46: 5 | D46: 1693 | E46: =TEXT(C46,"0000")&TEXT(D46,"00000000") -> 000500001693 | F46: =I46&E46 -> 27171610163000500001693 | G46: 75443520227263 | H46: 80 | I46: 27171610163 | J46: COMBIN SONIA NANCI | K46: 1 | L46: $ | M46: 13223.14 | N46: 0 | O46: 0 | P46: 0 | Q46: 2776.86 | R46: 16000
A47: 45965 | B47: 1 | C47: 18 | D47: 9317 | E47: =TEXT(C47,"0000")&TEXT(D47,"00000000") -> 001800009317 | F47: =I47&E47 -> 30601652044001800009317 | G47: 75444498650600 | H47: 80 | I47: 30601652044 | J47: ELECTRICIDAD COLOMBO S.A. | K47: 1 | L47: $ | M47: 63022.4 | N47: 0 | O47: 0 | P47: 0 | Q47: 13234.7 | R47: 76257.1
... A62: 45965 | B62: 1 | C62: 2 | D62: 2262 | E62: =TEXT(C62,"0000")&TEXT(D62,"00000000") -> 000200002262 | F62: =I62&E62 -> 20201399298000200002262 | G62: 75448453486360 | H62: 80 | I62: 20201399298 | J62: KLOSTER MARCELO ESTEBAN | K62: 1 | L62: $ | M62: 396496.76 | N62: 0 | O62: 0 | P62: 0 | Q62: 83264.32 | R62: 479761.07
A63: 45965 | B63: 1 | C63: 215 | D63: 100311 | E63: =TEXT(C63,"0000")&TEXT(D63,"00000000") -> 021500100311 | F63: =I63&E63 -> 30500529071021500100311 | G63: 35431670074949 | H63: 80 | I63: 30500529071 | J63: SAINT-GOBAIN ARGENTINA SA | K63: 1 | L63: $ | M63: 24359540 | P63: 1339774.7 | Q63: 5115503.4 | R63: 30814818
A64: 45965 | B64: 1 | C64: 215 | D64: 100312 | E64: =TEXT(C64,"0000")&TEXT(D64,"00000000") -> 021500100312 | F64: =I64&E64 -> 30500529071021500100312 | G64: 35431670074949 | H64: 80 | I64: 30500529071 | J64: SAINT-GOBAIN ARGENTINA SA | K64: 1 | L64: $ | M64: 198615.81 | P64: 10923.88 | Q64: 41709.32 | R64: 251249.01
A65: 45965 | B65: 3 | C65: 1203 | D65: 362 | E65: =TEXT(C65,"0000")&TEXT(D65,"00000000") -> 120300000362 | F65: =I65&E65 -> 30708492945120300000362 | G65: 75445446847861 | H65: 80 | I65: 30708492945 | J65: SINIS S. A. | K65: 1345.0068 | L65: USD | M65: 293.58 | N65: 0 | O65: 0 | P65: 0 | Q65: 61.65 | R65: 355.23
A66: 45965 | B66: 3 | C66: 333 | D66: 11234 | E66: =TEXT(C66,"0000")&TEXT(D66,"00000000") -> 033300011234 | F66: =I66&E66 -> 30646512952033300011234 | G66: 35432150758787 | H66: 80 | I66: 30646512952 | J66: PINTURERIAS REX S A | K66: 1 | L66: $ | M66: 71574.89 | N66: 0 | O66: 0 | P66: 0 | Q66: 15030.73 | R66: 86605.62
A67: 45965 | B67: 3 | C67: 333 | D67: 11236 | E67: =TEXT(C67,"0000")&TEXT(D67,"00000000") -> 033300011236 | F67: =I67&E67 -> 30646512952033300011236 | G67: 35432150758787 | H67: 80 | I67: 30646512952 | J67: PINTURERIAS REX S A | K67: 1 | L67: $ | M67: 41008.39 | N67: 0 | O67: 0 | P67: 0 | Q67: 8611.76 | R67: 49620.15
A68: 45965 | B68: 3 | C68: 333 | D68: 11237 | E68: =TEXT(C68,"0000")&TEXT(D68,"00000000") -> 033300011237 | F68: =I68&E68 -> 30646512952033300011237 | G68: 35432150758787 | H68: 80 | I68: 30646512952 | J68: PINTURERIAS REX S A | K68: 1 | L68: $ | M68: 34708.93 | N68: 0 | O68: 0 | P68: 0 | Q68: 7288.88 | R68: 41997.81
A69: 45965 | B69: 3 | C69: 32 | D69: 164767 | E69: =TEXT(C69,"0000")&TEXT(D69,"00000000") -> 003200164767 | F69: =I69&E69 -> 30621181838003200164767 | G69: 75448522531658 | H69: 80 | I69: 30621181838 | J69: DISAL S A | K69: 1 | L69: $ | M69: 45991331 | P69: 0 | Q69: 9658179.4 | R69: 55649510
...

Sheet Comparativo
A1: CODIGO | B1: DENOMINACION | C1: TD | D1: Nº DOCUMENTO | E1: IVA | F1: FECHA | G1: ESP | H1: SERIE | I1: NUMERO | J1: % IVA | K1: TOTAL | L1: GRAVADO | M1: EXEN/NO GRAV | N1: IVA | O1: IVA Percep | P1: IIBB Percep | Q1: OTROS | R1: EXCL.NET.GRAV | S1: Unido | T1: AFIP IVA | U1: Cmparacion IVA | V1: AFIP Total | W1: Cmparacion Total
A2: 000967 | B2: ZEOCAR SACI | C2: 80 | D2: 30562597464 | E2: I | F2: 22/09/2025 | G2: NCP | H2: A1 | I2: 000400025904 | J2: 21 | K2: -459949.14 | L2: -380123.26 | M2: 0 | N2: -79825.88 | O2: 0 | P2: 0 | Q2: 0 | R2: 0 | S2: 30562597464000400025904 | T2: NO | U2: NO | V2: NO | W2: NO
A3: 000015 | B3: ESCALERAS SIN FIN SOCIEDAD DE HECHO | C3: 80 | D3: 33620532229 | E3: I | F3: 01/10/2025 | G3: NCP | H3: A1 | I3: 000200007977 | J3: 21 | K3: -206388.15 | L3: -170568.72 | M3: 0 | N3: -35819.43 | O3: 0 | P3: 0 | Q3: 0 | R3: 0 | S3: 33620532229000200007977 | T3: NO | U3: NO | V3: NO | W3: NO
A4: 000001 | B4: AKZO NOBEL S.A. - (ALBA & CETOL) | C4: 80 | D4: 30500529454 | E4: I | F4: 03/10/2025 | G4: NCP | H4: A1 | I4: 026700171598 | J4: 21 | K4: -207657.9 | L4: -97841.1 | M4: 0 | N4: -20546.64 | O4: -2935.23 | P4: -2446.03 | Q4: -83888.9 | R4: 0 | S4: 30500529454026700171598 | T4: NO | U4: NO | V4: NO | W4: NO
A5: 000015 | B5: ESCALERAS SIN FIN SOCIEDAD DE HECHO | C5: 80 | D5: 33620532229 | E5: I | F5: 07/10/2025 | G5: NCP | H5: A1 | I5: 000200007985 | J5: 21 | K5: -1506196 | L5: -1244790.1 | M5: 0 | N5: -261405.92 | O5: 0 | P5: 0 | Q5: 0 | R5: 0 | S5: 33620532229000200007985 | T5: NO | U5: NO | V5: NO | W5: NO
A6: 000300 | B6: A A ABRASIVOS ARGENTINOS S.A.I.C. | C6: 80 | D6: 30501044551 | E6: I | F6: 08/10/2025 | G6: NCP | H6: A1 | I6: 000700219976 | J6: 21 | K6: -126936.9 | L6: -30431.38 | M6: 0 | N6: -6390.59 | O6: -912.94 | P6: -760.78 | Q6: -88441.21 | R6: 0 | S6: 30501044551000700219976 | T6: NO | U6: NO | V6: NO | W6: NO
A7: 000001 | B7: AKZO NOBEL S.A. - (ALBA & CETOL) | C7: 80 | D7: 30500529454 | E7: I | F7: 16/10/2025 | G7: NCP | H7: A1 | I7: 026700171749 | J7: 21 | K7: -75705.97 | L7: -62566.92 | M7: 0 | N7: -13139.05 | O7: 0 | P7: 0 | Q7: 0 | R7: 0 | S7: 30500529454026700171749 | T7: NO | U7: NO | V7: NO | W7: NO
A8: 000039 | B8: PREPAN S.A | C8: 80 | D8: 33522734549 | E8: I | F8: 23/10/2025 | G8: NCP | H8: A1 | I8: 002100242470 | J8: 21 | K8: -1668181.7 | L8: -1345307.8 | M8: 0 | N8: -282514.64 | O8: -40359.23 | P8: 0 | Q8: 0 | R8: 0 | S8: 33522734549002100242470 | T8: NO | U8: NO | V8: NO | W8: NO
A9: 000039 | B9: PREPAN S.A | C9: 80 | D9: 33522734549 | E9: I | F9: 23/10/2025 | G9: NCP | H9: A1 | I9: 002100242471 | J9: 21 | K9: -2276867.9 | L9: -1836183.8 | M9: 0 | N9: -385598.6 | O9: -55085.51 | P9: 0 | Q9: 0 | R9: 0 | S9: 33522734549002100242471 | T9: NO | U9: NO | V9: NO | W9: NO
A10: 000039 | B10: PREPAN S.A | C10: 80 | D10: 33522734549 | E10: I | F10: 23/10/2025 | G10: NCP | H10: A1 | I10: 002100242472 | J10: 21 | K10: -5106.02 | L10: -4117.76 | M10: 0 | N10: -864.73 | O10: -123.53 | P10: 0 | Q10: 0 | R10: 0 | S10: 33522734549002100242472 | T10: NO | U10: NO | V10: NO | W10: NO
A11: 000039 | B11: PREPAN S.A | C11: 80 | D11: 33522734549 | E11: I | F11: 23/10/2025 | G11: NCP | H11: A1 | I11: 002100242473 | J11: 21 | K11: -26593.75 | L11: -21446.57 | M11: 0 | N11: -4503.78 | O11: -643.4 | P11: 0 | Q11: 0 | R11: 0 | S11: 33522734549002100242473 | T11: NO | U11: NO | V11: NO | W11: NO
A12: 000039 | B12: PREPAN S.A | C12: 80 | D12: 33522734549 | E12: I | F12: 23/10/2025 | G12: NCP | H12: A1 | I12: 002100242474 | J12: 21 | K12: -383572.04 | L12: -309332.29 | M12: 0 | N12: -64959.78 | O12: -9279.97 | P12: 0 | Q12: 0 | R12: 0 | S12: 33522734549002100242474 | T12: NO | U12: NO | V12: NO | W12: NO
A13: 000102 | B13: FAIP S.A.I.C | C13: 80 | D13: 30523412236 | E13: I | F13: 24/10/2025 | G13: NCP | H13: A1 | I13: 001400012737 | J13: 21 | K13: -1089740 | L13: -900611.59 | M13: 0 | N13: -189128.43 | O13: 0 | P13: 0 | Q13: 0 | R13: 0 | S13: 30523412236001400012737 | T13: NO | U13: NO | V13: NO | W13: NO
... A226: Z9999O | B226: GROSS SERGIO FABIAN | C226: 80 | D226: 23179973219 | E226: M | F226: 30/11/2025 | G226: NF | H226: C | I226: 000200001053 | J226: 0 | K226: 72000 | L226: 0 | M226: 72000 | N226: 0 | O226: 0 | P226: 0 | Q226: 0 | R226: 0 | S226: 23179973219000200001053 | T226: NO | U226: NO | V226: NO | W226: NO
